Workbook

Sheet Склад
A1: СКЛАД — УЧЁТ ОСТАТКОВ ТОВАРОВ
A2: Автоматический расчёт: остаток = сумма прихода − сумма расхода
A3: № | B3: Наименование товара | C3: Единица | D3: Приход (кол.) | E3: Расход (кол.) | F3: Остаток (кол.) | G3: Статус
A4: 1 | D4: =IF(B4="","",SUMIF('Приход товаров'!B:B,B4,'Приход товаров'!C:C)) | E4: =IF(B4="","",SUMIF('Расход товаров'!B:B,B4,'Расход товаров'!C:C)) | F4: =IF(B4="","",D4-E4) | G4: =IF(B4="","",IF(F4>10,"В наличии",IF(F4>0,"Мало","Нет в наличии")))
A5: 2 | D5: =IF(B5="","",SUMIF('Приход товаров'!B:B,B5,'Приход товаров'!C:C)) | E5: =IF(B5="","",SUMIF('Расход товаров'!B:B,B5,'Расход товаров'!C:C)) | F5: =IF(B5="","",D5-E5) | G5: =IF(B5="","",IF(F5>10,"В наличии",IF(F5>0,"Мало","Нет в наличии")))
A6: 3 | D6: =IF(B6="","",SUMIF('Приход товаров'!B:B,B6,'Приход товаров'!C:C)) | E6: =IF(B6="","",SUMIF('Расход товаров'!B:B,B6,'Расход товаров'!C:C)) | F6: =IF(B6="","",D6-E6) | G6: =IF(B6="","",IF(F6>10,"В наличии",IF(F6>0,"Мало","Нет в наличии")))
A7: 4 | D7: =IF(B7="","",SUMIF('Приход товаров'!B:B,B7,'Приход товаров'!C:C)) | E7: =IF(B7="","",SUMIF('Расход товаров'!B:B,B7,'Расход товаров'!C:C)) | F7: =IF(B7="","",D7-E7) | G7: =IF(B7="","",IF(F7>10,"В наличии",IF(F7>0,"Мало","Нет в наличии")))
A8: 5 | D8: =IF(B8="","",SUMIF('Приход товаров'!B:B,B8,'Приход товаров'!C:C)) | E8: =IF(B8="","",SUMIF('Расход товаров'!B:B,B8,'Расход товаров'!C:C)) | F8: =IF(B8="","",D8-E8) | G8: =IF(B8="","",IF(F8>10,"В наличии",IF(F8>0,"Мало","Нет в наличии")))
A9: 6 | D9: =IF(B9="","",SUMIF('Приход товаров'!B:B,B9,'Приход товаров'!C:C)) | E9: =IF(B9="","",SUMIF('Расход товаров'!B:B,B9,'Расход товаров'!C:C)) | F9: =IF(B9="","",D9-E9) | G9: =IF(B9="","",IF(F9>10,"В наличии",IF(F9>0,"Мало","Нет в наличии")))
A10: 7 | D10: =IF(B10="","",SUMIF('Приход товаров'!B:B,B10,'Приход товаров'!C:C)) | E10: =IF(B10="","",SUMIF('Расход товаров'!B:B,B10,'Расход товаров'!C:C)) | F10: =IF(B10="","",D10-E10) | G10: =IF(B10="","",IF(F10>10,"В наличии",IF(F10>0,"Мало","Нет в наличии")))
A11: 8 | D11: =IF(B11="","",SUMIF('Приход товаров'!B:B,B11,'Приход товаров'!C:C)) | E11: =IF(B11="","",SUMIF('Расход товаров'!B:B,B11,'Расход товаров'!C:C)) | F11: =IF(B11="","",D11-E11) | G11: =IF(B11="","",IF(F11>10,"В наличии",IF(F11>0,"Мало","Нет в наличии")))
A12: 9 | D12: =IF(B12="","",SUMIF('Приход товаров'!B:B,B12,'Приход товаров'!C:C)) | E12: =IF(B12="","",SUMIF('Расход товаров'!B:B,B12,'Расход товаров'!C:C)) | F12: =IF(B12="","",D12-E12) | G12: =IF(B12="","",IF(F12>10,"В наличии",IF(F12>0,"Мало","Нет в наличии")))
A13: 10 | D13: =IF(B13="","",SUMIF('Приход товаров'!B:B,B13,'Приход товаров'!C:C)) | E13: =IF(B13="","",SUMIF('Расход товаров'!B:B,B13,'Расход товаров'!C:C)) | F13: =IF(B13="","",D13-E13) | G13: =IF(B13="","",IF(F13>10,"В наличии",IF(F13>0,"Мало","Нет в наличии")))
A14: 11 | D14: =IF(B14="","",SUMIF('Приход товаров'!B:B,B14,'Приход товаров'!C:C)) | E14: =IF(B14="","",SUMIF('Расход товаров'!B:B,B14,'Расход товаров'!C:C)) | F14: =IF(B14="","",D14-E14) | G14: =IF(B14="","",IF(F14>10,"В наличии",IF(F14>0,"Мало","Нет в наличии")))
A15: 12 | D15: =IF(B15="","",SUMIF('Приход товаров'!B:B,B15,'Приход товаров'!C:C)) | E15: =IF(B15="","",SUMIF('Расход товаров'!B:B,B15,'Расход товаров'!C:C)) | F15: =IF(B15="","",D15-E15) | G15: =IF(B15="","",IF(F15>10,"В наличии",IF(F15>0,"Мало","Нет в наличии")))
... A103: 100 | D103: =IF(B103="","",SUMIF('Приход товаров'!B:B,B103,'Приход товаров'!C:C)) | E103: =IF(B103="","",SUMIF('Расход товаров'!B:B,B103,'Расход товаров'!C:C)) | F103: =IF(B103="","",D103-E103) | G103: =IF(B103="","",IF(F103>10,"В наличии",IF(F103>0,"Мало","Нет в наличии")))
A104: ИТОГО: | D104: =SUM(D4:D103) | E104: =SUM(E4:E103) | F104: =SUM(F4:F103)

Sheet Приход товаров
A1: ПРИХОД ТОВАРОВ
A2: Здесь вводятся все поступления товаров. Склад обновляется автоматически.
A3: № | B3: Наименование товара | C3: Количество | D3: Цена за ед. (сум) | E3: Сумма (сум) | F3: Дата прихода
A4: 1 | E4: =IF(OR(C4="",D4=""),"",C4*D4)
A5: 2 | E5: =IF(OR(C5="",D5=""),"",C5*D5)
A6: 3 | E6: =IF(OR(C6="",D6=""),"",C6*D6)
A7: 4 | E7: =IF(OR(C7="",D7=""),"",C7*D7)
A8: 5 | E8: =IF(OR(C8="",D8=""),"",C8*D8)
A9: 6 | E9: =IF(OR(C9="",D9=""),"",C9*D9)
A10: 7 | E10: =IF(OR(C10="",D10=""),"",C10*D10)
A11: 8 | E11: =IF(OR(C11="",D11=""),"",C11*D11)
A12: 9 | E12: =IF(OR(C12="",D12=""),"",C12*D12)
A13: 10 | E13: =IF(OR(C13="",D13=""),"",C13*D13)
A14: 11 | E14: =IF(OR(C14="",D14=""),"",C14*D14)
A15: 12 | E15: =IF(OR(C15="",D15=""),"",C15*D15)
... A503: 500 | E503: =IF(OR(C503="",D503=""),"",C503*D503)
A504: ИТОГО: | E504: =SUM(E4:E503)

Sheet Расход товаров
A1: РАСХОД ТОВАРОВ
A2: Списание товаров. Остаток на складе уменьшается автоматически.
A3: № | B3: Наименование товара | C3: Количество | D3: Цена за ед. (сум) | E3: Сумма (сум) | F3: Дата расхода
A4: 1 | E4: =IF(OR(C4="",D4=""),"",C4*D4)
A5: 2 | E5: =IF(OR(C5="",D5=""),"",C5*D5)
A6: 3 | E6: =IF(OR(C6="",D6=""),"",C6*D6)
A7: 4 | E7: =IF(OR(C7="",D7=""),"",C7*D7)
A8: 5 | E8: =IF(OR(C8="",D8=""),"",C8*D8)
A9: 6 | E9: =IF(OR(C9="",D9=""),"",C9*D9)
A10: 7 | E10: =IF(OR(C10="",D10=""),"",C10*D10)
A11: 8 | E11: =IF(OR(C11="",D11=""),"",C11*D11)
A12: 9 | E12: =IF(OR(C12="",D12=""),"",C12*D12)
A13: 10 | E13: =IF(OR(C13="",D13=""),"",C13*D13)
A14: 11 | E14: =IF(OR(C14="",D14=""),"",C14*D14)
A15: 12 | E15: =IF(OR(C15="",D15=""),"",C15*D15)
... A503: 500 | E503: =IF(OR(C503="",D503=""),"",C503*D503)
A504: ИТОГО: | E504: =SUM(E4:E503)

Sheet Расходы
A1: РАСХОДЫ
A2: Введите дату — сумма автоматически попадёт в нужный месяц «Финансового результата».
A3: № | B3: Дата | C3: Сумма (сум) | D3: Статья расхода | E3: Ответственный | F3: Примечание
A4: 1
A5: 2
A6: 3
A7: 4
A8: 5
A9: 6
A10: 7
A11: 8
A12: 9
A13: 10
A14: 11
A15: 12
... A1003: 1000
A1004: ИТОГО: | C1004: =SUM(C4:C1003)

Sheet Финансовый результат
A1: ФИНАНСОВЫЙ РЕЗУЛЬТАТ
A2: Обзор доходов, расходов и прибыли по месяцам
A3: Месяц | B3: Доходы (сум) | C3: Расходы (сум) | D3: Прибыль (сум)
A4: Январь | B4: =SUMIF('Январь'!H:H,"Оплачено",'Январь'!F:F) | C4: =SUMPRODUCT((MONTH(IFERROR('Расходы'!B4:B1003,0))=1)*(YEAR(IFERROR('Расходы'!B4:B1003,0))=2026)*('Расходы'!C4:C1003)) | D4: =B4-C4
A5: Февраль | B5: =SUMIF('Февраль'!H:H,"Оплачено",'Февраль'!F:F) | C5: =SUMPRODUCT((MONTH(IFERROR('Расходы'!B4:B1003,0))=2)*(YEAR(IFERROR('Расходы'!B4:B1003,0))=2026)*('Расходы'!C4:C1003)) | D5: =B5-C5
A6: Март | B6: =SUMIF('Март'!H:H,"Оплачено",'Март'!F:F) | C6: =SUMPRODUCT((MONTH(IFERROR('Расходы'!B4:B1003,0))=3)*(YEAR(IFERROR('Расходы'!B4:B1003,0))=2026)*('Расходы'!C4:C1003)) | D6: =B6-C6
A7: Апрель | B7: =SUMIF('Апрель'!H:H,"Оплачено",'Апрель'!F:F) | C7: =SUMPRODUCT((MONTH(IFERROR('Расходы'!B4:B1003,0))=4)*(YEAR(IFERROR('Расходы'!B4:B1003,0))=2026)*('Расходы'!C4:C1003)) | D7: =B7-C7
A8: Май | B8: =SUMIF('Май'!H:H,"Оплачено",'Май'!F:F) | C8: =SUMPRODUCT((MONTH(IFERROR('Расходы'!B4:B1003,0))=5)*(YEAR(IFERROR('Расходы'!B4:B1003,0))=2026)*('Расходы'!C4:C1003)) | D8: =B8-C8
A9: Июнь | B9: =SUMIF('Июнь'!H:H,"Оплачено",'Июнь'!F:F) | C9: =SUMPRODUCT((MONTH(IFERROR('Расходы'!B4:B1003,0))=6)*(YEAR(IFERROR('Расходы'!B4:B1003,0))=2026)*('Расходы'!C4:C1003)) | D9: =B9-C9
A10: Июль | B10: =SUMIF('Июль'!H:H,"Оплачено",'Июль'!F:F) | C10: =SUMPRODUCT((MONTH(IFERROR('Расходы'!B4:B1003,0))=7)*(YEAR(IFERROR('Расходы'!B4:B1003,0))=2026)*('Расходы'!C4:C1003)) | D10: =B10-C10
A11: Август | B11: =SUMIF('Август'!H:H,"Оплачено",'Август'!F:F) | C11: =SUMPRODUCT((MONTH(IFERROR('Расходы'!B4:B1003,0))=8)*(YEAR(IFERROR('Расходы'!B4:B1003,0))=2026)*('Расходы'!C4:C1003)) | D11: =B11-C11
A12: Сентябрь | B12: =SUMIF('Сентябрь'!H:H,"Оплачено",'Сентябрь'!F:F) | C12: =SUMPRODUCT((MONTH(IFERROR('Расходы'!B4:B1003,0))=9)*(YEAR(IFERROR('Расходы'!B4:B1003,0))=2026)*('Расходы'!C4:C1003)) | D12: =B12-C12
A13: Октябрь | B13: =SUMIF('Октябрь'!H:H,"Оплачено",'Октябрь'!F:F) | C13: =SUMPRODUCT((MONTH(IFERROR('Расходы'!B4:B1003,0))=10)*(YEAR(IFERROR('Расходы'!B4:B1003,0))=2026)*('Расходы'!C4:C1003)) | D13: =B13-C13
A14: Ноябрь | B14: =SUMIF('Ноябрь'!H:H,"Оплачено",'Ноябрь'!F:F) | C14: =SUMPRODUCT((MONTH(IFERROR('Расходы'!B4:B1003,0))=11)*(YEAR(IFERROR('Расходы'!B4:B1003,0))=2026)*('Расходы'!C4:C1003)) | D14: =B14-C14
A15: Декабрь | B15: =SUMIF('Декабрь'!H:H,"Оплачено",'Декабрь'!F:F) | C15: =SUMPRODUCT((MONTH(IFERROR('Расходы'!B4:B1003,0))=12)*(YEAR(IFERROR('Расходы'!B4:B1003,0))=2026)*('Расходы'!C4:C1003)) | D15: =B15-C15
A16: ИТОГО: | B16: =SUM(B4:B15) | C16: =SUM(C4:C15) | D16: =B16-C16

Sheet Январь
A1: ДОХОДЫ — ЯНВАРЬ 2026
J2: Карта | L2: Наличные | N2: Терминал | P2: Перечисление
A3: № | B3: Покупатель | C3: Дата заказа | D3: № договора | E3: № счёт-фактуры | F3: Сумма (сум) | G3: Тип оплаты | H3: Статус оплаты | I3: Статус счёт-фактуры | J3: Оплачено | K3: Не оплачено | L3: Оплачено | M3: Не оплачено | N3: Оплачено | O3: Не оплачено | P3: Оплачено | Q3: Не оплачено
A4: 1 | J4: =IF(AND(G4="Карта",H4="Оплачено"),F4,"") | K4: =IF(AND(G4="Карта",H4="Не оплачено"),F4,"") | L4: =IF(AND(G4="Наличные",H4="Оплачено"),F4,"") | M4: =IF(AND(G4="Наличные",H4="Не оплачено"),F4,"") | N4: =IF(AND(G4="Терминал",H4="Оплачено"),F4,"") | O4: =IF(AND(G4="Терминал",H4="Не оплачено"),F4,"") | P4: =IF(AND(G4="Перечисление",H4="Оплачено"),F4,"") | Q4: =IF(AND(G4="Перечисление",H4="Не оплачено"),F4,"")
A5: 2 | J5: =IF(AND(G5="Карта",H5="Оплачено"),F5,"") | K5: =IF(AND(G5="Карта",H5="Не оплачено"),F5,"") | L5: =IF(AND(G5="Наличные",H5="Оплачено"),F5,"") | M5: =IF(AND(G5="Наличные",H5="Не оплачено"),F5,"") | N5: =IF(AND(G5="Терминал",H5="Оплачено"),F5,"") | O5: =IF(AND(G5="Терминал",H5="Не оплачено"),F5,"") | P5: =IF(AND(G5="Перечисление",H5="Оплачено"),F5,"") | Q5: =IF(AND(G5="Перечисление",H5="Не оплачено"),F5,"")
A6: 3 | J6: =IF(AND(G6="Карта",H6="Оплачено"),F6,"") | K6: =IF(AND(G6="Карта",H6="Не оплачено"),F6,"") | L6: =IF(AND(G6="Наличные",H6="Оплачено"),F6,"") | M6: =IF(AND(G6="Наличные",H6="Не оплачено"),F6,"") | N6: =IF(AND(G6="Терминал",H6="Оплачено"),F6,"") | O6: =IF(AND(G6="Терминал",H6="Не оплачено"),F6,"") | P6: =IF(AND(G6="Перечисление",H6="Оплачено"),F6,"") | Q6: =IF(AND(G6="Перечисление",H6="Не оплачено"),F6,"")
A7: 4 | J7: =IF(AND(G7="Карта",H7="Оплачено"),F7,"") | K7: =IF(AND(G7="Карта",H7="Не оплачено"),F7,"") | L7: =IF(AND(G7="Наличные",H7="Оплачено"),F7,"") | M7: =IF(AND(G7="Наличные",H7="Не оплачено"),F7,"") | N7: =IF(AND(G7="Терминал",H7="Оплачено"),F7,"") | O7: =IF(AND(G7="Терминал",H7="Не оплачено"),F7,"") | P7: =IF(AND(G7="Перечисление",H7="Оплачено"),F7,"") | Q7: =IF(AND(G7="Перечисление",H7="Не оплачено"),F7,"")
A8: 5 | J8: =IF(AND(G8="Карта",H8="Оплачено"),F8,"") | K8: =IF(AND(G8="Карта",H8="Не оплачено"),F8,"") | L8: =IF(AND(G8="Наличные",H8="Оплачено"),F8,"") | M8: =IF(AND(G8="Наличные",H8="Не оплачено"),F8,"") | N8: =IF(AND(G8="Терминал",H8="Оплачено"),F8,"") | O8: =IF(AND(G8="Терминал",H8="Не оплачено"),F8,"") | P8: =IF(AND(G8="Перечисление",H8="Оплачено"),F8,"") | Q8: =IF(AND(G8="Перечисление",H8="Не оплачено"),F8,"")
A9: 6 | J9: =IF(AND(G9="Карта",H9="Оплачено"),F9,"") | K9: =IF(AND(G9="Карта",H9="Не оплачено"),F9,"") | L9: =IF(AND(G9="Наличные",H9="Оплачено"),F9,"") | M9: =IF(AND(G9="Наличные",H9="Не оплачено"),F9,"") | N9: =IF(AND(G9="Терминал",H9="Оплачено"),F9,"") | O9: =IF(AND(G9="Терминал",H9="Не оплачено"),F9,"") | P9: =IF(AND(G9="Перечисление",H9="Оплачено"),F9,"") | Q9: =IF(AND(G9="Перечисление",H9="Не оплачено"),F9,"")
A10: 7 | J10: =IF(AND(G10="Карта",H10="Оплачено"),F10,"") | K10: =IF(AND(G10="Карта",H10="Не оплачено"),F10,"") | L10: =IF(AND(G10="Наличные",H10="Оплачено"),F10,"") | M10: =IF(AND(G10="Наличные",H10="Не оплачено"),F10,"") | N10: =IF(AND(G10="Терминал",H10="Оплачено"),F10,"") | O10: =IF(AND(G10="Терминал",H10="Не оплачено"),F10,"") | P10: =IF(AND(G10="Перечисление",H10="Оплачено"),F10,"") | Q10: =IF(AND(G10="Перечисление",H10="Не оплачено"),F10,"")
A11: 8 | J11: =IF(AND(G11="Карта",H11="Оплачено"),F11,"") | K11: =IF(AND(G11="Карта",H11="Не оплачено"),F11,"") | L11: =IF(AND(G11="Наличные",H11="Оплачено"),F11,"") | M11: =IF(AND(G11="Наличные",H11="Не оплачено"),F11,"") | N11: =IF(AND(G11="Терминал",H11="Оплачено"),F11,"") | O11: =IF(AND(G11="Терминал",H11="Не оплачено"),F11,"") | P11: =IF(AND(G11="Перечисление",H11="Оплачено"),F11,"") | Q11: =IF(AND(G11="Перечисление",H11="Не оплачено"),F11,"")
A12: 9 | J12: =IF(AND(G12="Карта",H12="Оплачено"),F12,"") | K12: =IF(AND(G12="Карта",H12="Не оплачено"),F12,"") | L12: =IF(AND(G12="Наличные",H12="Оплачено"),F12,"") | M12: =IF(AND(G12="Наличные",H12="Не оплачено"),F12,"") | N12: =IF(AND(G12="Терминал",H12="Оплачено"),F12,"") | O12: =IF(AND(G12="Терминал",H12="Не оплачено"),F12,"") | P12: =IF(AND(G12="Перечисление",H12="Оплачено"),F12,"") | Q12: =IF(AND(G12="Перечисление",H12="Не оплачено"),F12,"")
A13: 10 | J13: =IF(AND(G13="Карта",H13="Оплачено"),F13,"") | K13: =IF(AND(G13="Карта",H13="Не оплачено"),F13,"") | L13: =IF(AND(G13="Наличные",H13="Оплачено"),F13,"") | M13: =IF(AND(G13="Наличные",H13="Не оплачено"),F13,"") | N13: =IF(AND(G13="Терминал",H13="Оплачено"),F13,"") | O13: =IF(AND(G13="Терминал",H13="Не оплачено"),F13,"") | P13: =IF(AND(G13="Перечисление",H13="Оплачено"),F13,"") | Q13: =IF(AND(G13="Перечисление",H13="Не оплачено"),F13,"")
A14: 11 | J14: =IF(AND(G14="Карта",H14="Оплачено"),F14,"") | K14: =IF(AND(G14="Карта",H14="Не оплачено"),F14,"") | L14: =IF(AND(G14="Наличные",H14="Оплачено"),F14,"") | M14: =IF(AND(G14="Наличные",H14="Не оплачено"),F14,"") | N14: =IF(AND(G14="Терминал",H14="Оплачено"),F14,"") | O14: =IF(AND(G14="Терминал",H14="Не оплачено"),F14,"") | P14: =IF(AND(G14="Перечисление",H14="Оплачено"),F14,"") | Q14: =IF(AND(G14="Перечисление",H14="Не оплачено"),F14,"")
A15: 12 | J15: =IF(AND(G15="Карта",H15="Оплачено"),F15,"") | K15: =IF(AND(G15="Карта",H15="Не оплачено"),F15,"") | L15: =IF(AND(G15="Наличные",H15="Оплачено"),F15,"") | M15: =IF(AND(G15="Наличные",H15="Не оплачено"),F15,"") | N15: =IF(AND(G15="Терминал",H15="Оплачено"),F15,"") | O15: =IF(AND(G15="Терминал",H15="Не оплачено"),F15,"") | P15: =IF(AND(G15="Перечисление",H15="Оплачено"),F15,"") | Q15: =IF(AND(G15="Перечисление",H15="Не оплачено"),F15,"")
... A503: 500 | J503: =IF(AND(G503="Карта",H503="Оплачено"),F503,"") | K503: =IF(AND(G503="Карта",H503="Не оплачено"),F503,"") | L503: =IF(AND(G503="Наличные",H503="Оплачено"),F503,"") | M503: =IF(AND(G503="Наличные",H503="Не оплачено"),F503,"") | N503: =IF(AND(G503="Терминал",H503="Оплачено"),F503,"") | O503: =IF(AND(G503="Терминал",H503="Не оплачено"),F503,"") | P503: =IF(AND(G503="Перечисление",H503="Оплачено"),F503,"") | Q503: =IF(AND(G503="Перечисление",H503="Не оплачено"),F503,"")
A504: ИТОГО: | F504: =SUMIF(H4:H503,"Оплачено",F4:F503) | J504: =IFERROR(SUM(J4:J503),0) | K504: =IFERROR(SUM(K4:K503),0) | L504: =IFERROR(SUM(L4:L503),0) | M504: =IFERROR(SUM(M4:M503),0) | N504: =IFERROR(SUM(N4:N503),0) | O504: =IFERROR(SUM(O4:O503),0) | P504: =IFERROR(SUM(P4:P503),0) | Q504: =IFERROR(SUM(Q4:Q503),0)

Sheet Февраль
A1: ДОХОДЫ — ФЕВРАЛЬ 2026
J2: Карта | L2: Наличные | N2: Терминал | P2: Перечисление
A3: № | B3: Покупатель | C3: Дата заказа | D3: № договора | E3: № счёт-фактуры | F3: Сумма (сум) | G3: Тип оплаты | H3: Статус оплаты | I3: Статус счёт-фактуры | J3: Оплачено | K3: Не оплачено | L3: Оплачено | M3: Не оплачено | N3: Оплачено | O3: Не оплачено | P3: Оплачено | Q3: Не оплачено
A4: 1 | J4: =IF(AND(G4="Карта",H4="Оплачено"),F4,"") | K4: =IF(AND(G4="Карта",H4="Не оплачено"),F4,"") | L4: =IF(AND(G4="Наличные",H4="Оплачено"),F4,"") | M4: =IF(AND(G4="Наличные",H4="Не оплачено"),F4,"") | N4: =IF(AND(G4="Терминал",H4="Оплачено"),F4,"") | O4: =IF(AND(G4="Терминал",H4="Не оплачено"),F4,"") | P4: =IF(AND(G4="Перечисление",H4="Оплачено"),F4,"") | Q4: =IF(AND(G4="Перечисление",H4="Не оплачено"),F4,"")
A5: 2 | J5: =IF(AND(G5="Карта",H5="Оплачено"),F5,"") | K5: =IF(AND(G5="Карта",H5="Не оплачено"),F5,"") | L5: =IF(AND(G5="Наличные",H5="Оплачено"),F5,"") | M5: =IF(AND(G5="Наличные",H5="Не оплачено"),F5,"") | N5: =IF(AND(G5="Терминал",H5="Оплачено"),F5,"") | O5: =IF(AND(G5="Терминал",H5="Не оплачено"),F5,"") | P5: =IF(AND(G5="Перечисление",H5="Оплачено"),F5,"") | Q5: =IF(AND(G5="Перечисление",H5="Не оплачено"),F5,"")
A6: 3 | J6: =IF(AND(G6="Карта",H6="Оплачено"),F6,"") | K6: =IF(AND(G6="Карта",H6="Не оплачено"),F6,"") | L6: =IF(AND(G6="Наличные",H6="Оплачено"),F6,"") | M6: =IF(AND(G6="Наличные",H6="Не оплачено"),F6,"") | N6: =IF(AND(G6="Терминал",H6="Оплачено"),F6,"") | O6: =IF(AND(G6="Терминал",H6="Не оплачено"),F6,"") | P6: =IF(AND(G6="Перечисление",H6="Оплачено"),F6,"") | Q6: =IF(AND(G6="Перечисление",H6="Не оплачено"),F6,"")
A7: 4 | J7: =IF(AND(G7="Карта",H7="Оплачено"),F7,"") | K7: =IF(AND(G7="Карта",H7="Не оплачено"),F7,"") | L7: =IF(AND(G7="Наличные",H7="Оплачено"),F7,"") | M7: =IF(AND(G7="Наличные",H7="Не оплачено"),F7,"") | N7: =IF(AND(G7="Терминал",H7="Оплачено"),F7,"") | O7: =IF(AND(G7="Терминал",H7="Не оплачено"),F7,"") | P7: =IF(AND(G7="Перечисление",H7="Оплачено"),F7,"") | Q7: =IF(AND(G7="Перечисление",H7="Не оплачено"),F7,"")
A8: 5 | J8: =IF(AND(G8="Карта",H8="Оплачено"),F8,"") | K8: =IF(AND(G8="Карта",H8="Не оплачено"),F8,"") | L8: =IF(AND(G8="Наличные",H8="Оплачено"),F8,"") | M8: =IF(AND(G8="Наличные",H8="Не оплачено"),F8,"") | N8: =IF(AND(G8="Терминал",H8="Оплачено"),F8,"") | O8: =IF(AND(G8="Терминал",H8="Не оплачено"),F8,"") | P8: =IF(AND(G8="Перечисление",H8="Оплачено"),F8,"") | Q8: =IF(AND(G8="Перечисление",H8="Не оплачено"),F8,"")
A9: 6 | J9: =IF(AND(G9="Карта",H9="Оплачено"),F9,"") | K9: =IF(AND(G9="Карта",H9="Не оплачено"),F9,"") | L9: =IF(AND(G9="Наличные",H9="Оплачено"),F9,"") | M9: =IF(AND(G9="Наличные",H9="Не оплачено"),F9,"") | N9: =IF(AND(G9="Терминал",H9="Оплачено"),F9,"") | O9: =IF(AND(G9="Терминал",H9="Не оплачено"),F9,"") | P9: =IF(AND(G9="Перечисление",H9="Оплачено"),F9,"") | Q9: =IF(AND(G9="Перечисление",H9="Не оплачено"),F9,"")
A10: 7 | J10: =IF(AND(G10="Карта",H10="Оплачено"),F10,"") | K10: =IF(AND(G10="Карта",H10="Не оплачено"),F10,"") | L10: =IF(AND(G10="Наличные",H10="Оплачено"),F10,"") | M10: =IF(AND(G10="Наличные",H10="Не оплачено"),F10,"") | N10: =IF(AND(G10="Терминал",H10="Оплачено"),F10,"") | O10: =IF(AND(G10="Терминал",H10="Не оплачено"),F10,"") | P10: =IF(AND(G10="Перечисление",H10="Оплачено"),F10,"") | Q10: =IF(AND(G10="Перечисление",H10="Не оплачено"),F10,"")
A11: 8 | J11: =IF(AND(G11="Карта",H11="Оплачено"),F11,"") | K11: =IF(AND(G11="Карта",H11="Не оплачено"),F11,"") | L11: =IF(AND(G11="Наличные",H11="Оплачено"),F11,"") | M11: =IF(AND(G11="Наличные",H11="Не оплачено"),F11,"") | N11: =IF(AND(G11="Терминал",H11="Оплачено"),F11,"") | O11: =IF(AND(G11="Терминал",H11="Не оплачено"),F11,"") | P11: =IF(AND(G11="Перечисление",H11="Оплачено"),F11,"") | Q11: =IF(AND(G11="Перечисление",H11="Не оплачено"),F11,"")
A12: 9 | J12: =IF(AND(G12="Карта",H12="Оплачено"),F12,"") | K12: =IF(AND(G12="Карта",H12="Не оплачено"),F12,"") | L12: =IF(AND(G12="Наличные",H12="Оплачено"),F12,"") | M12: =IF(AND(G12="Наличные",H12="Не оплачено"),F12,"") | N12: =IF(AND(G12="Терминал",H12="Оплачено"),F12,"") | O12: =IF(AND(G12="Терминал",H12="Не оплачено"),F12,"") | P12: =IF(AND(G12="Перечисление",H12="Оплачено"),F12,"") | Q12: =IF(AND(G12="Перечисление",H12="Не оплачено"),F12,"")
A13: 10 | J13: =IF(AND(G13="Карта",H13="Оплачено"),F13,"") | K13: =IF(AND(G13="Карта",H13="Не оплачено"),F13,"") | L13: =IF(AND(G13="Наличные",H13="Оплачено"),F13,"") | M13: =IF(AND(G13="Наличные",H13="Не оплачено"),F13,"") | N13: =IF(AND(G13="Терминал",H13="Оплачено"),F13,"") | O13: =IF(AND(G13="Терминал",H13="Не оплачено"),F13,"") | P13: =IF(AND(G13="Перечисление",H13="Оплачено"),F13,"") | Q13: =IF(AND(G13="Перечисление",H13="Не оплачено"),F13,"")
A14: 11 | J14: =IF(AND(G14="Карта",H14="Оплачено"),F14,"") | K14: =IF(AND(G14="Карта",H14="Не оплачено"),F14,"") | L14: =IF(AND(G14="Наличные",H14="Оплачено"),F14,"") | M14: =IF(AND(G14="Наличные",H14="Не оплачено"),F14,"") | N14: =IF(AND(G14="Терминал",H14="Оплачено"),F14,"") | O14: =IF(AND(G14="Терминал",H14="Не оплачено"),F14,"") | P14: =IF(AND(G14="Перечисление",H14="Оплачено"),F14,"") | Q14: =IF(AND(G14="Перечисление",H14="Не оплачено"),F14,"")
A15: 12 | J15: =IF(AND(G15="Карта",H15="Оплачено"),F15,"") | K15: =IF(AND(G15="Карта",H15="Не оплачено"),F15,"") | L15: =IF(AND(G15="Наличные",H15="Оплачено"),F15,"") | M15: =IF(AND(G15="Наличные",H15="Не оплачено"),F15,"") | N15: =IF(AND(G15="Терминал",H15="Оплачено"),F15,"") | O15: =IF(AND(G15="Терминал",H15="Не оплачено"),F15,"") | P15: =IF(AND(G15="Перечисление",H15="Оплачено"),F15,"") | Q15: =IF(AND(G15="Перечисление",H15="Не оплачено"),F15,"")
... A503: 500 | J503: =IF(AND(G503="Карта",H503="Оплачено"),F503,"") | K503: =IF(AND(G503="Карта",H503="Не оплачено"),F503,"") | L503: =IF(AND(G503="Наличные",H503="Оплачено"),F503,"") | M503: =IF(AND(G503="Наличные",H503="Не оплачено"),F503,"") | N503: =IF(AND(G503="Терминал",H503="Оплачено"),F503,"") | O503: =IF(AND(G503="Терминал",H503="Не оплачено"),F503,"") | P503: =IF(AND(G503="Перечисление",H503="Оплачено"),F503,"") | Q503: =IF(AND(G503="Перечисление",H503="Не оплачено"),F503,"")
A504: ИТОГО: | F504: =SUMIF(H4:H503,"Оплачено",F4:F503) | J504: =IFERROR(SUM(J4:J503),0) | K504: =IFERROR(SUM(K4:K503),0) | L504: =IFERROR(SUM(L4:L503),0) | M504: =IFERROR(SUM(M4:M503),0) | N504: =IFERROR(SUM(N4:N503),0) | O504: =IFERROR(SUM(O4:O503),0) | P504: =IFERROR(SUM(P4:P503),0) | Q504: =IFERROR(SUM(Q4:Q503),0)

Sheet Март
A1: ДОХОДЫ — МАРТ 2026
J2: Карта | L2: Наличные | N2: Терминал | P2: Перечисление
A3: № | B3: Покупатель | C3: Дата заказа | D3: № договора | E3: № счёт-фактуры | F3: Сумма (сум) | G3: Тип оплаты | H3: Статус оплаты | I3: Статус счёт-фактуры | J3: Оплачено | K3: Не оплачено | L3: Оплачено | M3: Не оплачено | N3: Оплачено | O3: Не оплачено | P3: Оплачено | Q3: Не оплачено
A4: 1 | J4: =IF(AND(G4="Карта",H4="Оплачено"),F4,"") | K4: =IF(AND(G4="Карта",H4="Не оплачено"),F4,"") | L4: =IF(AND(G4="Наличные",H4="Оплачено"),F4,"") | M4: =IF(AND(G4="Наличные",H4="Не оплачено"),F4,"") | N4: =IF(AND(G4="Терминал",H4="Оплачено"),F4,"") | O4: =IF(AND(G4="Терминал",H4="Не оплачено"),F4,"") | P4: =IF(AND(G4="Перечисление",H4="Оплачено"),F4,"") | Q4: =IF(AND(G4="Перечисление",H4="Не оплачено"),F4,"")
A5: 2 | J5: =IF(AND(G5="Карта",H5="Оплачено"),F5,"") | K5: =IF(AND(G5="Карта",H5="Не оплачено"),F5,"") | L5: =IF(AND(G5="Наличные",H5="Оплачено"),F5,"") | M5: =IF(AND(G5="Наличные",H5="Не оплачено"),F5,"") | N5: =IF(AND(G5="Терминал",H5="Оплачено"),F5,"") | O5: =IF(AND(G5="Терминал",H5="Не оплачено"),F5,"") | P5: =IF(AND(G5="Перечисление",H5="Оплачено"),F5,"") | Q5: =IF(AND(G5="Перечисление",H5="Не оплачено"),F5,"")
A6: 3 | J6: =IF(AND(G6="Карта",H6="Оплачено"),F6,"") | K6: =IF(AND(G6="Карта",H6="Не оплачено"),F6,"") | L6: =IF(AND(G6="Наличные",H6="Оплачено"),F6,"") | M6: =IF(AND(G6="Наличные",H6="Не оплачено"),F6,"") | N6: =IF(AND(G6="Терминал",H6="Оплачено"),F6,"") | O6: =IF(AND(G6="Терминал",H6="Не оплачено"),F6,"") | P6: =IF(AND(G6="Перечисление",H6="Оплачено"),F6,"") | Q6: =IF(AND(G6="Перечисление",H6="Не оплачено"),F6,"")
A7: 4 | J7: =IF(AND(G7="Карта",H7="Оплачено"),F7,"") | K7: =IF(AND(G7="Карта",H7="Не оплачено"),F7,"") | L7: =IF(AND(G7="Наличные",H7="Оплачено"),F7,"") | M7: =IF(AND(G7="Наличные",H7="Не оплачено"),F7,"") | N7: =IF(AND(G7="Терминал",H7="Оплачено"),F7,"") | O7: =IF(AND(G7="Терминал",H7="Не оплачено"),F7,"") | P7: =IF(AND(G7="Перечисление",H7="Оплачено"),F7,"") | Q7: =IF(AND(G7="Перечисление",H7="Не оплачено"),F7,"")
A8: 5 | J8: =IF(AND(G8="Карта",H8="Оплачено"),F8,"") | K8: =IF(AND(G8="Карта",H8="Не оплачено"),F8,"") | L8: =IF(AND(G8="Наличные",H8="Оплачено"),F8,"") | M8: =IF(AND(G8="Наличные",H8="Не оплачено"),F8,"") | N8: =IF(AND(G8="Терминал",H8="Оплачено"),F8,"") | O8: =IF(AND(G8="Терминал",H8="Не оплачено"),F8,"") | P8: =IF(AND(G8="Перечисление",H8="Оплачено"),F8,"") | Q8: =IF(AND(G8="Перечисление",H8="Не оплачено"),F8,"")
A9: 6 | J9: =IF(AND(G9="Карта",H9="Оплачено"),F9,"") | K9: =IF(AND(G9="Карта",H9="Не оплачено"),F9,"") | L9: =IF(AND(G9="Наличные",H9="Оплачено"),F9,"") | M9: =IF(AND(G9="Наличные",H9="Не оплачено"),F9,"") | N9: =IF(AND(G9="Терминал",H9="Оплачено"),F9,"") | O9: =IF(AND(G9="Терминал",H9="Не оплачено"),F9,"") | P9: =IF(AND(G9="Перечисление",H9="Оплачено"),F9,"") | Q9: =IF(AND(G9="Перечисление",H9="Не оплачено"),F9,"")
A10: 7 | J10: =IF(AND(G10="Карта",H10="Оплачено"),F10,"") | K10: =IF(AND(G10="Карта",H10="Не оплачено"),F10,"") | L10: =IF(AND(G10="Наличные",H10="Оплачено"),F10,"") | M10: =IF(AND(G10="Наличные",H10="Не оплачено"),F10,"") | N10: =IF(AND(G10="Терминал",H10="Оплачено"),F10,"") | O10: =IF(AND(G10="Терминал",H10="Не оплачено"),F10,"") | P10: =IF(AND(G10="Перечисление",H10="Оплачено"),F10,"") | Q10: =IF(AND(G10="Перечисление",H10="Не оплачено"),F10,"")
A11: 8 | J11: =IF(AND(G11="Карта",H11="Оплачено"),F11,"") | K11: =IF(AND(G11="Карта",H11="Не оплачено"),F11,"") | L11: =IF(AND(G11="Наличные",H11="Оплачено"),F11,"") | M11: =IF(AND(G11="Наличные",H11="Не оплачено"),F11,"") | N11: =IF(AND(G11="Терминал",H11="Оплачено"),F11,"") | O11: =IF(AND(G11="Терминал",H11="Не оплачено"),F11,"") | P11: =IF(AND(G11="Перечисление",H11="Оплачено"),F11,"") | Q11: =IF(AND(G11="Перечисление",H11="Не оплачено"),F11,"")
A12: 9 | J12: =IF(AND(G12="Карта",H12="Оплачено"),F12,"") | K12: =IF(AND(G12="Карта",H12="Не оплачено"),F12,"") | L12: =IF(AND(G12="Наличные",H12="Оплачено"),F12,"") | M12: =IF(AND(G12="Наличные",H12="Не оплачено"),F12,"") | N12: =IF(AND(G12="Терминал",H12="Оплачено"),F12,"") | O12: =IF(AND(G12="Терминал",H12="Не оплачено"),F12,"") | P12: =IF(AND(G12="Перечисление",H12="Оплачено"),F12,"") | Q12: =IF(AND(G12="Перечисление",H12="Не оплачено"),F12,"")
A13: 10 | J13: =IF(AND(G13="Карта",H13="Оплачено"),F13,"") | K13: =IF(AND(G13="Карта",H13="Не оплачено"),F13,"") | L13: =IF(AND(G13="Наличные",H13="Оплачено"),F13,"") | M13: =IF(AND(G13="Наличные",H13="Не оплачено"),F13,"") | N13: =IF(AND(G13="Терминал",H13="Оплачено"),F13,"") | O13: =IF(AND(G13="Терминал",H13="Не оплачено"),F13,"") | P13: =IF(AND(G13="Перечисление",H13="Оплачено"),F13,"") | Q13: =IF(AND(G13="Перечисление",H13="Не оплачено"),F13,"")
A14: 11 | J14: =IF(AND(G14="Карта",H14="Оплачено"),F14,"") | K14: =IF(AND(G14="Карта",H14="Не оплачено"),F14,"") | L14: =IF(AND(G14="Наличные",H14="Оплачено"),F14,"") | M14: =IF(AND(G14="Наличные",H14="Не оплачено"),F14,"") | N14: =IF(AND(G14="Терминал",H14="Оплачено"),F14,"") | O14: =IF(AND(G14="Терминал",H14="Не оплачено"),F14,"") | P14: =IF(AND(G14="Перечисление",H14="Оплачено"),F14,"") | Q14: =IF(AND(G14="Перечисление",H14="Не оплачено"),F14,"")
A15: 12 | J15: =IF(AND(G15="Карта",H15="Оплачено"),F15,"") | K15: =IF(AND(G15="Карта",H15="Не оплачено"),F15,"") | L15: =IF(AND(G15="Наличные",H15="Оплачено"),F15,"") | M15: =IF(AND(G15="Наличные",H15="Не оплачено"),F15,"") | N15: =IF(AND(G15="Терминал",H15="Оплачено"),F15,"") | O15: =IF(AND(G15="Терминал",H15="Не оплачено"),F15,"") | P15: =IF(AND(G15="Перечисление",H15="Оплачено"),F15,"") | Q15: =IF(AND(G15="Перечисление",H15="Не оплачено"),F15,"")
... A503: 500 | J503: =IF(AND(G503="Карта",H503="Оплачено"),F503,"") | K503: =IF(AND(G503="Карта",H503="Не оплачено"),F503,"") | L503: =IF(AND(G503="Наличные",H503="Оплачено"),F503,"") | M503: =IF(AND(G503="Наличные",H503="Не оплачено"),F503,"") | N503: =IF(AND(G503="Терминал",H503="Оплачено"),F503,"") | O503: =IF(AND(G503="Терминал",H503="Не оплачено"),F503,"") | P503: =IF(AND(G503="Перечисление",H503="Оплачено"),F503,"") | Q503: =IF(AND(G503="Перечисление",H503="Не оплачено"),F503,"")
A504: ИТОГО: | F504: =SUMIF(H4:H503,"Оплачено",F4:F503) | J504: =IFERROR(SUM(J4:J503),0) | K504: =IFERROR(SUM(K4:K503),0) | L504: =IFERROR(SUM(L4:L503),0) | M504: =IFERROR(SUM(M4:M503),0) | N504: =IFERROR(SUM(N4:N503),0) | O504: =IFERROR(SUM(O4:O503),0) | P504: =IFERROR(SUM(P4:P503),0) | Q504: =IFERROR(SUM(Q4:Q503),0)

Sheet Апрель
A1: ДОХОДЫ — АПРЕЛЬ 2026
J2: Карта | L2: Наличные | N2: Терминал | P2: Перечисление
A3: № | B3: Покупатель | C3: Дата заказа | D3: № договора | E3: № счёт-фактуры | F3: Сумма (сум) | G3: Тип оплаты | H3: Статус оплаты | I3: Статус счёт-фактуры | J3: Оплачено | K3: Не оплачено | L3: Оплачено | M3: Не оплачено | N3: Оплачено | O3: Не оплачено | P3: Оплачено | Q3: Не оплачено
A4: 1 | J4: =IF(AND(G4="Карта",H4="Оплачено"),F4,"") | K4: =IF(AND(G4="Карта",H4="Не оплачено"),F4,"") | L4: =IF(AND(G4="Наличные",H4="Оплачено"),F4,"") | M4: =IF(AND(G4="Наличные",H4="Не оплачено"),F4,"") | N4: =IF(AND(G4="Терминал",H4="Оплачено"),F4,"") | O4: =IF(AND(G4="Терминал",H4="Не оплачено"),F4,"") | P4: =IF(AND(G4="Перечисление",H4="Оплачено"),F4,"") | Q4: =IF(AND(G4="Перечисление",H4="Не оплачено"),F4,"")
A5: 2 | J5: =IF(AND(G5="Карта",H5="Оплачено"),F5,"") | K5: =IF(AND(G5="Карта",H5="Не оплачено"),F5,"") | L5: =IF(AND(G5="Наличные",H5="Оплачено"),F5,"") | M5: =IF(AND(G5="Наличные",H5="Не оплачено"),F5,"") | N5: =IF(AND(G5="Терминал",H5="Оплачено"),F5,"") | O5: =IF(AND(G5="Терминал",H5="Не оплачено"),F5,"") | P5: =IF(AND(G5="Перечисление",H5="Оплачено"),F5,"") | Q5: =IF(AND(G5="Перечисление",H5="Не оплачено"),F5,"")
A6: 3 | J6: =IF(AND(G6="Карта",H6="Оплачено"),F6,"") | K6: =IF(AND(G6="Карта",H6="Не оплачено"),F6,"") | L6: =IF(AND(G6="Наличные",H6="Оплачено"),F6,"") | M6: =IF(AND(G6="Наличные",H6="Не оплачено"),F6,"") | N6: =IF(AND(G6="Терминал",H6="Оплачено"),F6,"") | O6: =IF(AND(G6="Терминал",H6="Не оплачено"),F6,"") | P6: =IF(AND(G6="Перечисление",H6="Оплачено"),F6,"") | Q6: =IF(AND(G6="Перечисление",H6="Не оплачено"),F6,"")
A7: 4 | J7: =IF(AND(G7="Карта",H7="Оплачено"),F7,"") | K7: =IF(AND(G7="Карта",H7="Не оплачено"),F7,"") | L7: =IF(AND(G7="Наличные",H7="Оплачено"),F7,"") | M7: =IF(AND(G7="Наличные",H7="Не оплачено"),F7,"") | N7: =IF(AND(G7="Терминал",H7="Оплачено"),F7,"") | O7: =IF(AND(G7="Терминал",H7="Не оплачено"),F7,"") | P7: =IF(AND(G7="Перечисление",H7="Оплачено"),F7,"") | Q7: =IF(AND(G7="Перечисление",H7="Не оплачено"),F7,"")
A8: 5 | J8: =IF(AND(G8="Карта",H8="Оплачено"),F8,"") | K8: =IF(AND(G8="Карта",H8="Не оплачено"),F8,"") | L8: =IF(AND(G8="Наличные",H8="Оплачено"),F8,"") | M8: =IF(AND(G8="Наличные",H8="Не оплачено"),F8,"") | N8: =IF(AND(G8="Терминал",H8="Оплачено"),F8,"") | O8: =IF(AND(G8="Терминал",H8="Не оплачено"),F8,"") | P8: =IF(AND(G8="Перечисление",H8="Оплачено"),F8,"") | Q8: =IF(AND(G8="Перечисление",H8="Не оплачено"),F8,"")
A9: 6 | J9: =IF(AND(G9="Карта",H9="Оплачено"),F9,"") | K9: =IF(AND(G9="Карта",H9="Не оплачено"),F9,"") | L9: =IF(AND(G9="Наличные",H9="Оплачено"),F9,"") | M9: =IF(AND(G9="Наличные",H9="Не оплачено"),F9,"") | N9: =IF(AND(G9="Терминал",H9="Оплачено"),F9,"") | O9: =IF(AND(G9="Терминал",H9="Не оплачено"),F9,"") | P9: =IF(AND(G9="Перечисление",H9="Оплачено"),F9,"") | Q9: =IF(AND(G9="Перечисление",H9="Не оплачено"),F9,"")
A10: 7 | J10: =IF(AND(G10="Карта",H10="Оплачено"),F10,"") | K10: =IF(AND(G10="Карта",H10="Не оплачено"),F10,"") | L10: =IF(AND(G10="Наличные",H10="Оплачено"),F10,"") | M10: =IF(AND(G10="Наличные",H10="Не оплачено"),F10,"") | N10: =IF(AND(G10="Терминал",H10="Оплачено"),F10,"") | O10: =IF(AND(G10="Терминал",H10="Не оплачено"),F10,"") | P10: =IF(AND(G10="Перечисление",H10="Оплачено"),F10,"") | Q10: =IF(AND(G10="Перечисление",H10="Не оплачено"),F10,"")
A11: 8 | J11: =IF(AND(G11="Карта",H11="Оплачено"),F11,"") | K11: =IF(AND(G11="Карта",H11="Не оплачено"),F11,"") | L11: =IF(AND(G11="Наличные",H11="Оплачено"),F11,"") | M11: =IF(AND(G11="Наличные",H11="Не оплачено"),F11,"") | N11: =IF(AND(G11="Терминал",H11="Оплачено"),F11,"") | O11: =IF(AND(G11="Терминал",H11="Не оплачено"),F11,"") | P11: =IF(AND(G11="Перечисление",H11="Оплачено"),F11,"") | Q11: =IF(AND(G11="Перечисление",H11="Не оплачено"),F11,"")
A12: 9 | J12: =IF(AND(G12="Карта",H12="Оплачено"),F12,"") | K12: =IF(AND(G12="Карта",H12="Не оплачено"),F12,"") | L12: =IF(AND(G12="Наличные",H12="Оплачено"),F12,"") | M12: =IF(AND(G12="Наличные",H12="Не оплачено"),F12,"") | N12: =IF(AND(G12="Терминал",H12="Оплачено"),F12,"") | O12: =IF(AND(G12="Терминал",H12="Не оплачено"),F12,"") | P12: =IF(AND(G12="Перечисление",H12="Оплачено"),F12,"") | Q12: =IF(AND(G12="Перечисление",H12="Не оплачено"),F12,"")
A13: 10 | J13: =IF(AND(G13="Карта",H13="Оплачено"),F13,"") | K13: =IF(AND(G13="Карта",H13="Не оплачено"),F13,"") | L13: =IF(AND(G13="Наличные",H13="Оплачено"),F13,"") | M13: =IF(AND(G13="Наличные",H13="Не оплачено"),F13,"") | N13: =IF(AND(G13="Терминал",H13="Оплачено"),F13,"") | O13: =IF(AND(G13="Терминал",H13="Не оплачено"),F13,"") | P13: =IF(AND(G13="Перечисление",H13="Оплачено"),F13,"") | Q13: =IF(AND(G13="Перечисление",H13="Не оплачено"),F13,"")
A14: 11 | J14: =IF(AND(G14="Карта",H14="Оплачено"),F14,"") | K14: =IF(AND(G14="Карта",H14="Не оплачено"),F14,"") | L14: =IF(AND(G14="Наличные",H14="Оплачено"),F14,"") | M14: =IF(AND(G14="Наличные",H14="Не оплачено"),F14,"") | N14: =IF(AND(G14="Терминал",H14="Оплачено"),F14,"") | O14: =IF(AND(G14="Терминал",H14="Не оплачено"),F14,"") | P14: =IF(AND(G14="Перечисление",H14="Оплачено"),F14,"") | Q14: =IF(AND(G14="Перечисление",H14="Не оплачено"),F14,"")
A15: 12 | J15: =IF(AND(G15="Карта",H15="Оплачено"),F15,"") | K15: =IF(AND(G15="Карта",H15="Не оплачено"),F15,"") | L15: =IF(AND(G15="Наличные",H15="Оплачено"),F15,"") | M15: =IF(AND(G15="Наличные",H15="Не оплачено"),F15,"") | N15: =IF(AND(G15="Терминал",H15="Оплачено"),F15,"") | O15: =IF(AND(G15="Терминал",H15="Не оплачено"),F15,"") | P15: =IF(AND(G15="Перечисление",H15="Оплачено"),F15,"") | Q15: =IF(AND(G15="Перечисление",H15="Не оплачено"),F15,"")
... A503: 500 | J503: =IF(AND(G503="Карта",H503="Оплачено"),F503,"") | K503: =IF(AND(G503="Карта",H503="Не оплачено"),F503,"") | L503: =IF(AND(G503="Наличные",H503="Оплачено"),F503,"") | M503: =IF(AND(G503="Наличные",H503="Не оплачено"),F503,"") | N503: =IF(AND(G503="Терминал",H503="Оплачено"),F503,"") | O503: =IF(AND(G503="Терминал",H503="Не оплачено"),F503,"") | P503: =IF(AND(G503="Перечисление",H503="Оплачено"),F503,"") | Q503: =IF(AND(G503="Перечисление",H503="Не оплачено"),F503,"")
A504: ИТОГО: | F504: =SUMIF(H4:H503,"Оплачено",F4:F503) | J504: =IFERROR(SUM(J4:J503),0) | K504: =IFERROR(SUM(K4:K503),0) | L504: =IFERROR(SUM(L4:L503),0) | M504: =IFERROR(SUM(M4:M503),0) | N504: =IFERROR(SUM(N4:N503),0) | O504: =IFERROR(SUM(O4:O503),0) | P504: =IFERROR(SUM(P4:P503),0) | Q504: =IFERROR(SUM(Q4:Q503),0)

Sheet Май
A1: ДОХОДЫ — МАЙ 2026
J2: Карта | L2: Наличные | N2: Терминал | P2: Перечисление
A3: № | B3: Покупатель | C3: Дата заказа | D3: № договора | E3: № счёт-фактуры | F3: Сумма (сум) | G3: Тип оплаты | H3: Статус оплаты | I3: Статус счёт-фактуры | J3: Оплачено | K3: Не оплачено | L3: Оплачено | M3: Не оплачено | N3: Оплачено | O3: Не оплачено | P3: Оплачено | Q3: Не оплачено
A4: 1 | J4: =IF(AND(G4="Карта",H4="Оплачено"),F4,"") | K4: =IF(AND(G4="Карта",H4="Не оплачено"),F4,"") | L4: =IF(AND(G4="Наличные",H4="Оплачено"),F4,"") | M4: =IF(AND(G4="Наличные",H4="Не оплачено"),F4,"") | N4: =IF(AND(G4="Терминал",H4="Оплачено"),F4,"") | O4: =IF(AND(G4="Терминал",H4="Не оплачено"),F4,"") | P4: =IF(AND(G4="Перечисление",H4="Оплачено"),F4,"") | Q4: =IF(AND(G4="Перечисление",H4="Не оплачено"),F4,"")
A5: 2 | J5: =IF(AND(G5="Карта",H5="Оплачено"),F5,"") | K5: =IF(AND(G5="Карта",H5="Не оплачено"),F5,"") | L5: =IF(AND(G5="Наличные",H5="Оплачено"),F5,"") | M5: =IF(AND(G5="Наличные",H5="Не оплачено"),F5,"") | N5: =IF(AND(G5="Терминал",H5="Оплачено"),F5,"") | O5: =IF(AND(G5="Терминал",H5="Не оплачено"),F5,"") | P5: =IF(AND(G5="Перечисление",H5="Оплачено"),F5,"") | Q5: =IF(AND(G5="Перечисление",H5="Не оплачено"),F5,"")
A6: 3 | J6: =IF(AND(G6="Карта",H6="Оплачено"),F6,"") | K6: =IF(AND(G6="Карта",H6="Не оплачено"),F6,"") | L6: =IF(AND(G6="Наличные",H6="Оплачено"),F6,"") | M6: =IF(AND(G6="Наличные",H6="Не оплачено"),F6,"") | N6: =IF(AND(G6="Терминал",H6="Оплачено"),F6,"") | O6: =IF(AND(G6="Терминал",H6="Не оплачено"),F6,"") | P6: =IF(AND(G6="Перечисление",H6="Оплачено"),F6,"") | Q6: =IF(AND(G6="Перечисление",H6="Не оплачено"),F6,"")
A7: 4 | J7: =IF(AND(G7="Карта",H7="Оплачено"),F7,"") | K7: =IF(AND(G7="Карта",H7="Не оплачено"),F7,"") | L7: =IF(AND(G7="Наличные",H7="Оплачено"),F7,"") | M7: =IF(AND(G7="Наличные",H7="Не оплачено"),F7,"") | N7: =IF(AND(G7="Терминал",H7="Оплачено"),F7,"") | O7: =IF(AND(G7="Терминал",H7="Не оплачено"),F7,"") | P7: =IF(AND(G7="Перечисление",H7="Оплачено"),F7,"") | Q7: =IF(AND(G7="Перечисление",H7="Не оплачено"),F7,"")
A8: 5 | J8: =IF(AND(G8="Карта",H8="Оплачено"),F8,"") | K8: =IF(AND(G8="Карта",H8="Не оплачено"),F8,"") | L8: =IF(AND(G8="Наличные",H8="Оплачено"),F8,"") | M8: =IF(AND(G8="Наличные",H8="Не оплачено"),F8,"") | N8: =IF(AND(G8="Терминал",H8="Оплачено"),F8,"") | O8: =IF(AND(G8="Терминал",H8="Не оплачено"),F8,"") | P8: =IF(AND(G8="Перечисление",H8="Оплачено"),F8,"") | Q8: =IF(AND(G8="Перечисление",H8="Не оплачено"),F8,"")
A9: 6 | J9: =IF(AND(G9="Карта",H9="Оплачено"),F9,"") | K9: =IF(AND(G9="Карта",H9="Не оплачено"),F9,"") | L9: =IF(AND(G9="Наличные",H9="Оплачено"),F9,"") | M9: =IF(AND(G9="Наличные",H9="Не оплачено"),F9,"") | N9: =IF(AND(G9="Терминал",H9="Оплачено"),F9,"") | O9: =IF(AND(G9="Терминал",H9="Не оплачено"),F9,"") | P9: =IF(AND(G9="Перечисление",H9="Оплачено"),F9,"") | Q9: =IF(AND(G9="Перечисление",H9="Не оплачено"),F9,"")
A10: 7 | J10: =IF(AND(G10="Карта",H10="Оплачено"),F10,"") | K10: =IF(AND(G10="Карта",H10="Не оплачено"),F10,"") | L10: =IF(AND(G10="Наличные",H10="Оплачено"),F10,"") | M10: =IF(AND(G10="Наличные",H10="Не оплачено"),F10,"") | N10: =IF(AND(G10="Терминал",H10="Оплачено"),F10,"") | O10: =IF(AND(G10="Терминал",H10="Не оплачено"),F10,"") | P10: =IF(AND(G10="Перечисление",H10="Оплачено"),F10,"") | Q10: =IF(AND(G10="Перечисление",H10="Не оплачено"),F10,"")
A11: 8 | J11: =IF(AND(G11="Карта",H11="Оплачено"),F11,"") | K11: =IF(AND(G11="Карта",H11="Не оплачено"),F11,"") | L11: =IF(AND(G11="Наличные",H11="Оплачено"),F11,"") | M11: =IF(AND(G11="Наличные",H11="Не оплачено"),F11,"") | N11: =IF(AND(G11="Терминал",H11="Оплачено"),F11,"") | O11: =IF(AND(G11="Терминал",H11="Не оплачено"),F11,"") | P11: =IF(AND(G11="Перечисление",H11="Оплачено"),F11,"") | Q11: =IF(AND(G11="Перечисление",H11="Не оплачено"),F11,"")
A12: 9 | J12: =IF(AND(G12="Карта",H12="Оплачено"),F12,"") | K12: =IF(AND(G12="Карта",H12="Не оплачено"),F12,"") | L12: =IF(AND(G12="Наличные",H12="Оплачено"),F12,"") | M12: =IF(AND(G12="Наличные",H12="Не оплачено"),F12,"") | N12: =IF(AND(G12="Терминал",H12="Оплачено"),F12,"") | O12: =IF(AND(G12="Терминал",H12="Не оплачено"),F12,"") | P12: =IF(AND(G12="Перечисление",H12="Оплачено"),F12,"") | Q12: =IF(AND(G12="Перечисление",H12="Не оплачено"),F12,"")
A13: 10 | J13: =IF(AND(G13="Карта",H13="Оплачено"),F13,"") | K13: =IF(AND(G13="Карта",H13="Не оплачено"),F13,"") | L13: =IF(AND(G13="Наличные",H13="Оплачено"),F13,"") | M13: =IF(AND(G13="Наличные",H13="Не оплачено"),F13,"") | N13: =IF(AND(G13="Терминал",H13="Оплачено"),F13,"") | O13: =IF(AND(G13="Терминал",H13="Не оплачено"),F13,"") | P13: =IF(AND(G13="Перечисление",H13="Оплачено"),F13,"") | Q13: =IF(AND(G13="Перечисление",H13="Не оплачено"),F13,"")
A14: 11 | J14: =IF(AND(G14="Карта",H14="Оплачено"),F14,"") | K14: =IF(AND(G14="Карта",H14="Не оплачено"),F14,"") | L14: =IF(AND(G14="Наличные",H14="Оплачено"),F14,"") | M14: =IF(AND(G14="Наличные",H14="Не оплачено"),F14,"") | N14: =IF(AND(G14="Терминал",H14="Оплачено"),F14,"") | O14: =IF(AND(G14="Терминал",H14="Не оплачено"),F14,"") | P14: =IF(AND(G14="Перечисление",H14="Оплачено"),F14,"") | Q14: =IF(AND(G14="Перечисление",H14="Не оплачено"),F14,"")
A15: 12 | J15: =IF(AND(G15="Карта",H15="Оплачено"),F15,"") | K15: =IF(AND(G15="Карта",H15="Не оплачено"),F15,"") | L15: =IF(AND(G15="Наличные",H15="Оплачено"),F15,"") | M15: =IF(AND(G15="Наличные",H15="Не оплачено"),F15,"") | N15: =IF(AND(G15="Терминал",H15="Оплачено"),F15,"") | O15: =IF(AND(G15="Терминал",H15="Не оплачено"),F15,"") | P15: =IF(AND(G15="Перечисление",H15="Оплачено"),F15,"") | Q15: =IF(AND(G15="Перечисление",H15="Не оплачено"),F15,"")
... A503: 500 | J503: =IF(AND(G503="Карта",H503="Оплачено"),F503,"") | K503: =IF(AND(G503="Карта",H503="Не оплачено"),F503,"") | L503: =IF(AND(G503="Наличные",H503="Оплачено"),F503,"") | M503: =IF(AND(G503="Наличные",H503="Не оплачено"),F503,"") | N503: =IF(AND(G503="Терминал",H503="Оплачено"),F503,"") | O503: =IF(AND(G503="Терминал",H503="Не оплачено"),F503,"") | P503: =IF(AND(G503="Перечисление",H503="Оплачено"),F503,"") | Q503: =IF(AND(G503="Перечисление",H503="Не оплачено"),F503,"")
A504: ИТОГО: | F504: =SUMIF(H4:H503,"Оплачено",F4:F503) | J504: =IFERROR(SUM(J4:J503),0) | K504: =IFERROR(SUM(K4:K503),0) | L504: =IFERROR(SUM(L4:L503),0) | M504: =IFERROR(SUM(M4:M503),0) | N504: =IFERROR(SUM(N4:N503),0) | O504: =IFERROR(SUM(O4:O503),0) | P504: =IFERROR(SUM(P4:P503),0) | Q504: =IFERROR(SUM(Q4:Q503),0)

Sheet Июнь
A1: ДОХОДЫ — ИЮНЬ 2026
J2: Карта | L2: Наличные | N2: Терминал | P2: Перечисление
A3: № | B3: Покупатель | C3: Дата заказа | D3: № договора | E3: № счёт-фактуры | F3: Сумма (сум) | G3: Тип оплаты | H3: Статус оплаты | I3: Статус счёт-фактуры | J3: Оплачено | K3: Не оплачено | L3: Оплачено | M3: Не оплачено | N3: Оплачено | O3: Не оплачено | P3: Оплачено | Q3: Не оплачено
A4: 1 | J4: =IF(AND(G4="Карта",H4="Оплачено"),F4,"") | K4: =IF(AND(G4="Карта",H4="Не оплачено"),F4,"") | L4: =IF(AND(G4="Наличные",H4="Оплачено"),F4,"") | M4: =IF(AND(G4="Наличные",H4="Не оплачено"),F4,"") | N4: =IF(AND(G4="Терминал",H4="Оплачено"),F4,"") | O4: =IF(AND(G4="Терминал",H4="Не оплачено"),F4,"") | P4: =IF(AND(G4="Перечисление",H4="Оплачено"),F4,"") | Q4: =IF(AND(G4="Перечисление",H4="Не оплачено"),F4,"")
A5: 2 | J5: =IF(AND(G5="Карта",H5="Оплачено"),F5,"") | K5: =IF(AND(G5="Карта",H5="Не оплачено"),F5,"") | L5: =IF(AND(G5="Наличные",H5="Оплачено"),F5,"") | M5: =IF(AND(G5="Наличные",H5="Не оплачено"),F5,"") | N5: =IF(AND(G5="Терминал",H5="Оплачено"),F5,"") | O5: =IF(AND(G5="Терминал",H5="Не оплачено"),F5,"") | P5: =IF(AND(G5="Перечисление",H5="Оплачено"),F5,"") | Q5: =IF(AND(G5="Перечисление",H5="Не оплачено"),F5,"")
A6: 3 | J6: =IF(AND(G6="Карта",H6="Оплачено"),F6,"") | K6: =IF(AND(G6="Карта",H6="Не оплачено"),F6,"") | L6: =IF(AND(G6="Наличные",H6="Оплачено"),F6,"") | M6: =IF(AND(G6="Наличные",H6="Не оплачено"),F6,"") | N6: =IF(AND(G6="Терминал",H6="Оплачено"),F6,"") | O6: =IF(AND(G6="Терминал",H6="Не оплачено"),F6,"") | P6: =IF(AND(G6="Перечисление",H6="Оплачено"),F6,"") | Q6: =IF(AND(G6="Перечисление",H6="Не оплачено"),F6,"")
A7: 4 | J7: =IF(AND(G7="Карта",H7="Оплачено"),F7,"") | K7: =IF(AND(G7="Карта",H7="Не оплачено"),F7,"") | L7: =IF(AND(G7="Наличные",H7="Оплачено"),F7,"") | M7: =IF(AND(G7="Наличные",H7="Не оплачено"),F7,"") | N7: =IF(AND(G7="Терминал",H7="Оплачено"),F7,"") | O7: =IF(AND(G7="Терминал",H7="Не оплачено"),F7,"") | P7: =IF(AND(G7="Перечисление",H7="Оплачено"),F7,"") | Q7: =IF(AND(G7="Перечисление",H7="Не оплачено"),F7,"")
A8: 5 | J8: =IF(AND(G8="Карта",H8="Оплачено"),F8,"") | K8: =IF(AND(G8="Карта",H8="Не оплачено"),F8,"") | L8: =IF(AND(G8="Наличные",H8="Оплачено"),F8,"") | M8: =IF(AND(G8="Наличные",H8="Не оплачено"),F8,"") | N8: =IF(AND(G8="Терминал",H8="Оплачено"),F8,"") | O8: =IF(AND(G8="Терминал",H8="Не оплачено"),F8,"") | P8: =IF(AND(G8="Перечисление",H8="Оплачено"),F8,"") | Q8: =IF(AND(G8="Перечисление",H8="Не оплачено"),F8,"")
A9: 6 | J9: =IF(AND(G9="Карта",H9="Оплачено"),F9,"") | K9: =IF(AND(G9="Карта",H9="Не оплачено"),F9,"") | L9: =IF(AND(G9="Наличные",H9="Оплачено"),F9,"") | M9: =IF(AND(G9="Наличные",H9="Не оплачено"),F9,"") | N9: =IF(AND(G9="Терминал",H9="Оплачено"),F9,"") | O9: =IF(AND(G9="Терминал",H9="Не оплачено"),F9,"") | P9: =IF(AND(G9="Перечисление",H9="Оплачено"),F9,"") | Q9: =IF(AND(G9="Перечисление",H9="Не оплачено"),F9,"")
A10: 7 | J10: =IF(AND(G10="Карта",H10="Оплачено"),F10,"") | K10: =IF(AND(G10="Карта",H10="Не оплачено"),F10,"") | L10: =IF(AND(G10="Наличные",H10="Оплачено"),F10,"") | M10: =IF(AND(G10="Наличные",H10="Не оплачено"),F10,"") | N10: =IF(AND(G10="Терминал",H10="Оплачено"),F10,"") | O10: =IF(AND(G10="Терминал",H10="Не оплачено"),F10,"") | P10: =IF(AND(G10="Перечисление",H10="Оплачено"),F10,"") | Q10: =IF(AND(G10="Перечисление",H10="Не оплачено"),F10,"")
A11: 8 | J11: =IF(AND(G11="Карта",H11="Оплачено"),F11,"") | K11: =IF(AND(G11="Карта",H11="Не оплачено"),F11,"") | L11: =IF(AND(G11="Наличные",H11="Оплачено"),F11,"") | M11: =IF(AND(G11="Наличные",H11="Не оплачено"),F11,"") | N11: =IF(AND(G11="Терминал",H11="Оплачено"),F11,"") | O11: =IF(AND(G11="Терминал",H11="Не оплачено"),F11,"") | P11: =IF(AND(G11="Перечисление",H11="Оплачено"),F11,"") | Q11: =IF(AND(G11="Перечисление",H11="Не оплачено"),F11,"")
A12: 9 | J12: =IF(AND(G12="Карта",H12="Оплачено"),F12,"") | K12: =IF(AND(G12="Карта",H12="Не оплачено"),F12,"") | L12: =IF(AND(G12="Наличные",H12="Оплачено"),F12,"") | M12: =IF(AND(G12="Наличные",H12="Не оплачено"),F12,"") | N12: =IF(AND(G12="Терминал",H12="Оплачено"),F12,"") | O12: =IF(AND(G12="Терминал",H12="Не оплачено"),F12,"") | P12: =IF(AND(G12="Перечисление",H12="Оплачено"),F12,"") | Q12: =IF(AND(G12="Перечисление",H12="Не оплачено"),F12,"")
A13: 10 | J13: =IF(AND(G13="Карта",H13="Оплачено"),F13,"") | K13: =IF(AND(G13="Карта",H13="Не оплачено"),F13,"") | L13: =IF(AND(G13="Наличные",H13="Оплачено"),F13,"") | M13: =IF(AND(G13="Наличные",H13="Не оплачено"),F13,"") | N13: =IF(AND(G13="Терминал",H13="Оплачено"),F13,"") | O13: =IF(AND(G13="Терминал",H13="Не оплачено"),F13,"") | P13: =IF(AND(G13="Перечисление",H13="Оплачено"),F13,"") | Q13: =IF(AND(G13="Перечисление",H13="Не оплачено"),F13,"")
A14: 11 | J14: =IF(AND(G14="Карта",H14="Оплачено"),F14,"") | K14: =IF(AND(G14="Карта",H14="Не оплачено"),F14,"") | L14: =IF(AND(G14="Наличные",H14="Оплачено"),F14,"") | M14: =IF(AND(G14="Наличные",H14="Не оплачено"),F14,"") | N14: =IF(AND(G14="Терминал",H14="Оплачено"),F14,"") | O14: =IF(AND(G14="Терминал",H14="Не оплачено"),F14,"") | P14: =IF(AND(G14="Перечисление",H14="Оплачено"),F14,"") | Q14: =IF(AND(G14="Перечисление",H14="Не оплачено"),F14,"")
A15: 12 | J15: =IF(AND(G15="Карта",H15="Оплачено"),F15,"") | K15: =IF(AND(G15="Карта",H15="Не оплачено"),F15,"") | L15: =IF(AND(G15="Наличные",H15="Оплачено"),F15,"") | M15: =IF(AND(G15="Наличные",H15="Не оплачено"),F15,"") | N15: =IF(AND(G15="Терминал",H15="Оплачено"),F15,"") | O15: =IF(AND(G15="Терминал",H15="Не оплачено"),F15,"") | P15: =IF(AND(G15="Перечисление",H15="Оплачено"),F15,"") | Q15: =IF(AND(G15="Перечисление",H15="Не оплачено"),F15,"")
... A503: 500 | J503: =IF(AND(G503="Карта",H503="Оплачено"),F503,"") | K503: =IF(AND(G503="Карта",H503="Не оплачено"),F503,"") | L503: =IF(AND(G503="Наличные",H503="Оплачено"),F503,"") | M503: =IF(AND(G503="Наличные",H503="Не оплачено"),F503,"") | N503: =IF(AND(G503="Терминал",H503="Оплачено"),F503,"") | O503: =IF(AND(G503="Терминал",H503="Не оплачено"),F503,"") | P503: =IF(AND(G503="Перечисление",H503="Оплачено"),F503,"") | Q503: =IF(AND(G503="Перечисление",H503="Не оплачено"),F503,"")
A504: ИТОГО: | F504: =SUMIF(H4:H503,"Оплачено",F4:F503) | J504: =IFERROR(SUM(J4:J503),0) | K504: =IFERROR(SUM(K4:K503),0) | L504: =IFERROR(SUM(L4:L503),0) | M504: =IFERROR(SUM(M4:M503),0) | N504: =IFERROR(SUM(N4:N503),0) | O504: =IFERROR(SUM(O4:O503),0) | P504: =IFERROR(SUM(P4:P503),0) | Q504: =IFERROR(SUM(Q4:Q503),0)

Sheet Июль
A1: ДОХОДЫ — ИЮЛЬ 2026
J2: Карта | L2: Наличные | N2: Терминал | P2: Перечисление
A3: № | B3: Покупатель | C3: Дата заказа | D3: № договора | E3: № счёт-фактуры | F3: Сумма (сум) | G3: Тип оплаты | H3: Статус оплаты | I3: Статус счёт-фактуры | J3: Оплачено | K3: Не оплачено | L3: Оплачено | M3: Не оплачено | N3: Оплачено | O3: Не оплачено | P3: Оплачено | Q3: Не оплачено
A4: 1 | J4: =IF(AND(G4="Карта",H4="Оплачено"),F4,"") | K4: =IF(AND(G4="Карта",H4="Не оплачено"),F4,"") | L4: =IF(AND(G4="Наличные",H4="Оплачено"),F4,"") | M4: =IF(AND(G4="Наличные",H4="Не оплачено"),F4,"") | N4: =IF(AND(G4="Терминал",H4="Оплачено"),F4,"") | O4: =IF(AND(G4="Терминал",H4="Не оплачено"),F4,"") | P4: =IF(AND(G4="Перечисление",H4="Оплачено"),F4,"") | Q4: =IF(AND(G4="Перечисление",H4="Не оплачено"),F4,"")
A5: 2 | J5: =IF(AND(G5="Карта",H5="Оплачено"),F5,"") | K5: =IF(AND(G5="Карта",H5="Не оплачено"),F5,"") | L5: =IF(AND(G5="Наличные",H5="Оплачено"),F5,"") | M5: =IF(AND(G5="Наличные",H5="Не оплачено"),F5,"") | N5: =IF(AND(G5="Терминал",H5="Оплачено"),F5,"") | O5: =IF(AND(G5="Терминал",H5="Не оплачено"),F5,"") | P5: =IF(AND(G5="Перечисление",H5="Оплачено"),F5,"") | Q5: =IF(AND(G5="Перечисление",H5="Не оплачено"),F5,"")
A6: 3 | J6: =IF(AND(G6="Карта",H6="Оплачено"),F6,"") | K6: =IF(AND(G6="Карта",H6="Не оплачено"),F6,"") | L6: =IF(AND(G6="Наличные",H6="Оплачено"),F6,"") | M6: =IF(AND(G6="Наличные",H6="Не оплачено"),F6,"") | N6: =IF(AND(G6="Терминал",H6="Оплачено"),F6,"") | O6: =IF(AND(G6="Терминал",H6="Не оплачено"),F6,"") | P6: =IF(AND(G6="Перечисление",H6="Оплачено"),F6,"") | Q6: =IF(AND(G6="Перечисление",H6="Не оплачено"),F6,"")
A7: 4 | J7: =IF(AND(G7="Карта",H7="Оплачено"),F7,"") | K7: =IF(AND(G7="Карта",H7="Не оплачено"),F7,"") | L7: =IF(AND(G7="Наличные",H7="Оплачено"),F7,"") | M7: =IF(AND(G7="Наличные",H7="Не оплачено"),F7,"") | N7: =IF(AND(G7="Терминал",H7="Оплачено"),F7,"") | O7: =IF(AND(G7="Терминал",H7="Не оплачено"),F7,"") | P7: =IF(AND(G7="Перечисление",H7="Оплачено"),F7,"") | Q7: =IF(AND(G7="Перечисление",H7="Не оплачено"),F7,"")
A8: 5 | J8: =IF(AND(G8="Карта",H8="Оплачено"),F8,"") | K8: =IF(AND(G8="Карта",H8="Не оплачено"),F8,"") | L8: =IF(AND(G8="Наличные",H8="Оплачено"),F8,"") | M8: =IF(AND(G8="Наличные",H8="Не оплачено"),F8,"") | N8: =IF(AND(G8="Терминал",H8="Оплачено"),F8,"") | O8: =IF(AND(G8="Терминал",H8="Не оплачено"),F8,"") | P8: =IF(AND(G8="Перечисление",H8="Оплачено"),F8,"") | Q8: =IF(AND(G8="Перечисление",H8="Не оплачено"),F8,"")
A9: 6 | J9: =IF(AND(G9="Карта",H9="Оплачено"),F9,"") | K9: =IF(AND(G9="Карта",H9="Не оплачено"),F9,"") | L9: =IF(AND(G9="Наличные",H9="Оплачено"),F9,"") | M9: =IF(AND(G9="Наличные",H9="Не оплачено"),F9,"") | N9: =IF(AND(G9="Терминал",H9="Оплачено"),F9,"") | O9: =IF(AND(G9="Терминал",H9="Не оплачено"),F9,"") | P9: =IF(AND(G9="Перечисление",H9="Оплачено"),F9,"") | Q9: =IF(AND(G9="Перечисление",H9="Не оплачено"),F9,"")
A10: 7 | J10: =IF(AND(G10="Карта",H10="Оплачено"),F10,"") | K10: =IF(AND(G10="Карта",H10="Не оплачено"),F10,"") | L10: =IF(AND(G10="Наличные",H10="Оплачено"),F10,"") | M10: =IF(AND(G10="Наличные",H10="Не оплачено"),F10,"") | N10: =IF(AND(G10="Терминал",H10="Оплачено"),F10,"") | O10: =IF(AND(G10="Терминал",H10="Не оплачено"),F10,"") | P10: =IF(AND(G10="Перечисление",H10="Оплачено"),F10,"") | Q10: =IF(AND(G10="Перечисление",H10="Не оплачено"),F10,"")
A11: 8 | J11: =IF(AND(G11="Карта",H11="Оплачено"),F11,"") | K11: =IF(AND(G11="Карта",H11="Не оплачено"),F11,"") | L11: =IF(AND(G11="Наличные",H11="Оплачено"),F11,"") | M11: =IF(AND(G11="Наличные",H11="Не оплачено"),F11,"") | N11: =IF(AND(G11="Терминал",H11="Оплачено"),F11,"") | O11: =IF(AND(G11="Терминал",H11="Не оплачено"),F11,"") | P11: =IF(AND(G11="Перечисление",H11="Оплачено"),F11,"") | Q11: =IF(AND(G11="Перечисление",H11="Не оплачено"),F11,"")
A12: 9 | J12: =IF(AND(G12="Карта",H12="Оплачено"),F12,"") | K12: =IF(AND(G12="Карта",H12="Не оплачено"),F12,"") | L12: =IF(AND(G12="Наличные",H12="Оплачено"),F12,"") | M12: =IF(AND(G12="Наличные",H12="Не оплачено"),F12,"") | N12: =IF(AND(G12="Терминал",H12="Оплачено"),F12,"") | O12: =IF(AND(G12="Терминал",H12="Не оплачено"),F12,"") | P12: =IF(AND(G12="Перечисление",H12="Оплачено"),F12,"") | Q12: =IF(AND(G12="Перечисление",H12="Не оплачено"),F12,"")
A13: 10 | J13: =IF(AND(G13="Карта",H13="Оплачено"),F13,"") | K13: =IF(AND(G13="Карта",H13="Не оплачено"),F13,"") | L13: =IF(AND(G13="Наличные",H13="Оплачено"),F13,"") | M13: =IF(AND(G13="Наличные",H13="Не оплачено"),F13,"") | N13: =IF(AND(G13="Терминал",H13="Оплачено"),F13,"") | O13: =IF(AND(G13="Терминал",H13="Не оплачено"),F13,"") | P13: =IF(AND(G13="Перечисление",H13="Оплачено"),F13,"") | Q13: =IF(AND(G13="Перечисление",H13="Не оплачено"),F13,"")
A14: 11 | J14: =IF(AND(G14="Карта",H14="Оплачено"),F14,"") | K14: =IF(AND(G14="Карта",H14="Не оплачено"),F14,"") | L14: =IF(AND(G14="Наличные",H14="Оплачено"),F14,"") | M14: =IF(AND(G14="Наличные",H14="Не оплачено"),F14,"") | N14: =IF(AND(G14="Терминал",H14="Оплачено"),F14,"") | O14: =IF(AND(G14="Терминал",H14="Не оплачено"),F14,"") | P14: =IF(AND(G14="Перечисление",H14="Оплачено"),F14,"") | Q14: =IF(AND(G14="Перечисление",H14="Не оплачено"),F14,"")
A15: 12 | J15: =IF(AND(G15="Карта",H15="Оплачено"),F15,"") | K15: =IF(AND(G15="Карта",H15="Не оплачено"),F15,"") | L15: =IF(AND(G15="Наличные",H15="Оплачено"),F15,"") | M15: =IF(AND(G15="Наличные",H15="Не оплачено"),F15,"") | N15: =IF(AND(G15="Терминал",H15="Оплачено"),F15,"") | O15: =IF(AND(G15="Терминал",H15="Не оплачено"),F15,"") | P15: =IF(AND(G15="Перечисление",H15="Оплачено"),F15,"") | Q15: =IF(AND(G15="Перечисление",H15="Не оплачено"),F15,"")
... A503: 500 | J503: =IF(AND(G503="Карта",H503="Оплачено"),F503,"") | K503: =IF(AND(G503="Карта",H503="Не оплачено"),F503,"") | L503: =IF(AND(G503="Наличные",H503="Оплачено"),F503,"") | M503: =IF(AND(G503="Наличные",H503="Не оплачено"),F503,"") | N503: =IF(AND(G503="Терминал",H503="Оплачено"),F503,"") | O503: =IF(AND(G503="Терминал",H503="Не оплачено"),F503,"") | P503: =IF(AND(G503="Перечисление",H503="Оплачено"),F503,"") | Q503: =IF(AND(G503="Перечисление",H503="Не оплачено"),F503,"")
A504: ИТОГО: | F504: =SUMIF(H4:H503,"Оплачено",F4:F503) | J504: =IFERROR(SUM(J4:J503),0) | K504: =IFERROR(SUM(K4:K503),0) | L504: =IFERROR(SUM(L4:L503),0) | M504: =IFERROR(SUM(M4:M503),0) | N504: =IFERROR(SUM(N4:N503),0) | O504: =IFERROR(SUM(O4:O503),0) | P504: =IFERROR(SUM(P4:P503),0) | Q504: =IFERROR(SUM(Q4:Q503),0)

Sheet Август
A1: ДОХОДЫ — АВГУСТ 2026
J2: Карта | L2: Наличные | N2: Терминал | P2: Перечисление
A3: № | B3: Покупатель | C3: Дата заказа | D3: № договора | E3: № счёт-фактуры | F3: Сумма (сум) | G3: Тип оплаты | H3: Статус оплаты | I3: Статус счёт-фактуры | J3: Оплачено | K3: Не оплачено | L3: Оплачено | M3: Не оплачено | N3: Оплачено | O3: Не оплачено | P3: Оплачено | Q3: Не оплачено
A4: 1 | J4: =IF(AND(G4="Карта",H4="Оплачено"),F4,"") | K4: =IF(AND(G4="Карта",H4="Не оплачено"),F4,"") | L4: =IF(AND(G4="Наличные",H4="Оплачено"),F4,"") | M4: =IF(AND(G4="Наличные",H4="Не оплачено"),F4,"") | N4: =IF(AND(G4="Терминал",H4="Оплачено"),F4,"") | O4: =IF(AND(G4="Терминал",H4="Не оплачено"),F4,"") | P4: =IF(AND(G4="Перечисление",H4="Оплачено"),F4,"") | Q4: =IF(AND(G4="Перечисление",H4="Не оплачено"),F4,"")
A5: 2 | J5: =IF(AND(G5="Карта",H5="Оплачено"),F5,"") | K5: =IF(AND(G5="Карта",H5="Не оплачено"),F5,"") | L5: =IF(AND(G5="Наличные",H5="Оплачено"),F5,"") | M5: =IF(AND(G5="Наличные",H5="Не оплачено"),F5,"") | N5: =IF(AND(G5="Терминал",H5="Оплачено"),F5,"") | O5: =IF(AND(G5="Терминал",H5="Не оплачено"),F5,"") | P5: =IF(AND(G5="Перечисление",H5="Оплачено"),F5,"") | Q5: =IF(AND(G5="Перечисление",H5="Не оплачено"),F5,"")
A6: 3 | J6: =IF(AND(G6="Карта",H6="Оплачено"),F6,"") | K6: =IF(AND(G6="Карта",H6="Не оплачено"),F6,"") | L6: =IF(AND(G6="Наличные",H6="Оплачено"),F6,"") | M6: =IF(AND(G6="Наличные",H6="Не оплачено"),F6,"") | N6: =IF(AND(G6="Терминал",H6="Оплачено"),F6,"") | O6: =IF(AND(G6="Терминал",H6="Не оплачено"),F6,"") | P6: =IF(AND(G6="Перечисление",H6="Оплачено"),F6,"") | Q6: =IF(AND(G6="Перечисление",H6="Не оплачено"),F6,"")
A7: 4 | J7: =IF(AND(G7="Карта",H7="Оплачено"),F7,"") | K7: =IF(AND(G7="Карта",H7="Не оплачено"),F7,"") | L7: =IF(AND(G7="Наличные",H7="Оплачено"),F7,"") | M7: =IF(AND(G7="Наличные",H7="Не оплачено"),F7,"") | N7: =IF(AND(G7="Терминал",H7="Оплачено"),F7,"") | O7: =IF(AND(G7="Терминал",H7="Не оплачено"),F7,"") | P7: =IF(AND(G7="Перечисление",H7="Оплачено"),F7,"") | Q7: =IF(AND(G7="Перечисление",H7="Не оплачено"),F7,"")
A8: 5 | J8: =IF(AND(G8="Карта",H8="Оплачено"),F8,"") | K8: =IF(AND(G8="Карта",H8="Не оплачено"),F8,"") | L8: =IF(AND(G8="Наличные",H8="Оплачено"),F8,"") | M8: =IF(AND(G8="Наличные",H8="Не оплачено"),F8,"") | N8: =IF(AND(G8="Терминал",H8="Оплачено"),F8,"") | O8: =IF(AND(G8="Терминал",H8="Не оплачено"),F8,"") | P8: =IF(AND(G8="Перечисление",H8="Оплачено"),F8,"") | Q8: =IF(AND(G8="Перечисление",H8="Не оплачено"),F8,"")
A9: 6 | J9: =IF(AND(G9="Карта",H9="Оплачено"),F9,"") | K9: =IF(AND(G9="Карта",H9="Не оплачено"),F9,"") | L9: =IF(AND(G9="Наличные",H9="Оплачено"),F9,"") | M9: =IF(AND(G9="Наличные",H9="Не оплачено"),F9,"") | N9: =IF(AND(G9="Терминал",H9="Оплачено"),F9,"") | O9: =IF(AND(G9="Терминал",H9="Не оплачено"),F9,"") | P9: =IF(AND(G9="Перечисление",H9="Оплачено"),F9,"") | Q9: =IF(AND(G9="Перечисление",H9="Не оплачено"),F9,"")
A10: 7 | J10: =IF(AND(G10="Карта",H10="Оплачено"),F10,"") | K10: =IF(AND(G10="Карта",H10="Не оплачено"),F10,"") | L10: =IF(AND(G10="Наличные",H10="Оплачено"),F10,"") | M10: =IF(AND(G10="Наличные",H10="Не оплачено"),F10,"") | N10: =IF(AND(G10="Терминал",H10="Оплачено"),F10,"") | O10: =IF(AND(G10="Терминал",H10="Не оплачено"),F10,"") | P10: =IF(AND(G10="Перечисление",H10="Оплачено"),F10,"") | Q10: =IF(AND(G10="Перечисление",H10="Не оплачено"),F10,"")
A11: 8 | J11: =IF(AND(G11="Карта",H11="Оплачено"),F11,"") | K11: =IF(AND(G11="Карта",H11="Не оплачено"),F11,"") | L11: =IF(AND(G11="Наличные",H11="Оплачено"),F11,"") | M11: =IF(AND(G11="Наличные",H11="Не оплачено"),F11,"") | N11: =IF(AND(G11="Терминал",H11="Оплачено"),F11,"") | O11: =IF(AND(G11="Терминал",H11="Не оплачено"),F11,"") | P11: =IF(AND(G11="Перечисление",H11="Оплачено"),F11,"") | Q11: =IF(AND(G11="Перечисление",H11="Не оплачено"),F11,"")
A12: 9 | J12: =IF(AND(G12="Карта",H12="Оплачено"),F12,"") | K12: =IF(AND(G12="Карта",H12="Не оплачено"),F12,"") | L12: =IF(AND(G12="Наличные",H12="Оплачено"),F12,"") | M12: =IF(AND(G12="Наличные",H12="Не оплачено"),F12,"") | N12: =IF(AND(G12="Терминал",H12="Оплачено"),F12,"") | O12: =IF(AND(G12="Терминал",H12="Не оплачено"),F12,"") | P12: =IF(AND(G12="Перечисление",H12="Оплачено"),F12,"") | Q12: =IF(AND(G12="Перечисление",H12="Не оплачено"),F12,"")
A13: 10 | J13: =IF(AND(G13="Карта",H13="Оплачено"),F13,"") | K13: =IF(AND(G13="Карта",H13="Не оплачено"),F13,"") | L13: =IF(AND(G13="Наличные",H13="Оплачено"),F13,"") | M13: =IF(AND(G13="Наличные",H13="Не оплачено"),F13,"") | N13: =IF(AND(G13="Терминал",H13="Оплачено"),F13,"") | O13: =IF(AND(G13="Терминал",H13="Не оплачено"),F13,"") | P13: =IF(AND(G13="Перечисление",H13="Оплачено"),F13,"") | Q13: =IF(AND(G13="Перечисление",H13="Не оплачено"),F13,"")
A14: 11 | J14: =IF(AND(G14="Карта",H14="Оплачено"),F14,"") | K14: =IF(AND(G14="Карта",H14="Не оплачено"),F14,"") | L14: =IF(AND(G14="Наличные",H14="Оплачено"),F14,"") | M14: =IF(AND(G14="Наличные",H14="Не оплачено"),F14,"") | N14: =IF(AND(G14="Терминал",H14="Оплачено"),F14,"") | O14: =IF(AND(G14="Терминал",H14="Не оплачено"),F14,"") | P14: =IF(AND(G14="Перечисление",H14="Оплачено"),F14,"") | Q14: =IF(AND(G14="Перечисление",H14="Не оплачено"),F14,"")
A15: 12 | J15: =IF(AND(G15="Карта",H15="Оплачено"),F15,"") | K15: =IF(AND(G15="Карта",H15="Не оплачено"),F15,"") | L15: =IF(AND(G15="Наличные",H15="Оплачено"),F15,"") | M15: =IF(AND(G15="Наличные",H15="Не оплачено"),F15,"") | N15: =IF(AND(G15="Терминал",H15="Оплачено"),F15,"") | O15: =IF(AND(G15="Терминал",H15="Не оплачено"),F15,"") | P15: =IF(AND(G15="Перечисление",H15="Оплачено"),F15,"") | Q15: =IF(AND(G15="Перечисление",H15="Не оплачено"),F15,"")
... A503: 500 | J503: =IF(AND(G503="Карта",H503="Оплачено"),F503,"") | K503: =IF(AND(G503="Карта",H503="Не оплачено"),F503,"") | L503: =IF(AND(G503="Наличные",H503="Оплачено"),F503,"") | M503: =IF(AND(G503="Наличные",H503="Не оплачено"),F503,"") | N503: =IF(AND(G503="Терминал",H503="Оплачено"),F503,"") | O503: =IF(AND(G503="Терминал",H503="Не оплачено"),F503,"") | P503: =IF(AND(G503="Перечисление",H503="Оплачено"),F503,"") | Q503: =IF(AND(G503="Перечисление",H503="Не оплачено"),F503,"")
A504: ИТОГО: | F504: =SUMIF(H4:H503,"Оплачено",F4:F503) | J504: =IFERROR(SUM(J4:J503),0) | K504: =IFERROR(SUM(K4:K503),0) | L504: =IFERROR(SUM(L4:L503),0) | M504: =IFERROR(SUM(M4:M503),0) | N504: =IFERROR(SUM(N4:N503),0) | O504: =IFERROR(SUM(O4:O503),0) | P504: =IFERROR(SUM(P4:P503),0) | Q504: =IFERROR(SUM(Q4:Q503),0)

Sheet Сентябрь
A1: ДОХОДЫ — СЕНТЯБРЬ 2026
